Workbook
Name DepartmentFilterList: Employee_Lookups!$O$4:$O$10
Name ReportingYearList: Employee_Lookups!$P$4:$P$10

Sheet Dashboard
B1: NEXACORE TECHNOLOGIES — EXECUTIVE HR & WORKFORCE ANALYTICS DASHBOARD
B2: Observation Window: FY 2019 – FY 2025 | Reporting Cutoff: 2025-12-31 | Synthetic Portfolio Dataset (n = 1,450 Unique Employees)
B4: Select Department Filter: | C4: All Departments | E4: Select Reporting Year: | F4: 2025 | H4: Department filter updates workforce KPIs; year filter updates hires and exits. Attrition KPI is fixed to FY2025.
B6: ACTIVE HEADCOUNT (AS OF CUTOFF) | D6: NEW HIRES (SELECTED YEAR) | F6: TOTAL EXITS (SELECTED YEAR) | H6: FY2025 ATTRITION RATE | J6: AVG TENURE (ACTIVE STAFF) | L6: ACTIVE OVERTIME PARTICIPATION
B7: =IF($C$4="All Departments",KPI_Calculations!D12,INDEX(KPI_Calculations!D6:D11,MATCH($C$4,KPI_Calculations!A6:A11,0))) -> 1042 | D7: =IF($C$4="All Departments",COUNTIF(Cleaned_Data!$AB$2:$AB$1451,$F$4),COUNTIFS(Cleaned_Data!$D$2:$D$1451,$C$4,Cleaned_Data!$AB$2:$AB$1451,$F$4)) -> 221 | F7: =IF($C$4="All Departments",COUNTIF(Cleaned_Data!$AC$2:$AC$1451,$F$4),COUNTIFS(Cleaned_Data!$D$2:$D$1451,$C$4,Cleaned_Data!$AC$2:$AC$1451,$F$4)) -> 102 | H7: =IF($C$4="All Departments",KPI_Calculations!N12,INDEX(KPI_Calculations!N6:N11,MATCH($C$4,KPI_Calculations!A6:A11,0))) -> 0.10381679 | J7: =IF($C$4="All Departments",KPI_Calculations!O12,INDEX(KPI_Calculations!O6:O11,MATCH($C$4,KPI_Calculations!A6:A11,0))) -> 2.6975048 | L7: =IF($C$4="All Departments",KPI_Calculations!R12,INDEX(KPI_Calculations!R6:R11,MATCH($C$4,KPI_Calculations!A6:A11,0))) -> 0.3646833
B8: ="Target: "&TEXT(IF($C$4="All Departments",KPI_Calculations!C12,INDEX(KPI_Calculations!C6:C11,MATCH($C$4,KPI_Calculations!A6:A11,0))),"#,##0")&" | Variance: "&TEXT(IF($C$4="All Departments",KPI_Calculations!E12,INDEX(KPI_Calculations!E6:E11,MATCH($C$4,KPI_Calculations!A6:A11,0))),"+0;-0;0") -> Target: 1,095 | Variance: -53 | D8: ="Total Cohort Hired (19-25): "&TEXT(IF($C$4="All Departments",KPI_Calculations!F12,INDEX(KPI_Calculations!F6:F11,MATCH($C$4,KPI_Calculations!A6:A11,0))),"#,##0") -> Total Cohort Hired (19-25): 1,450 | F8: ="Cumulative Exits (19-25): "&TEXT(IF($C$4="All Departments",KPI_Calculations!G12,INDEX(KPI_Calculations!G6:G11,MATCH($C$4,KPI_Calculations!A6:A11,0))),"#,##0") -> Cumulative Exits (19-25): 408 | H8: ="Cohort Attrition: "&TEXT(IF($C$4="All Departments",KPI_Calculations!I12,INDEX(KPI_Calculations!I6:I11,MATCH($C$4,KPI_Calculations!A6:A11,0))),"0.0%") -> Cohort Attrition: 28.1% | J8: ="Avg Perf Rating: "&TEXT(IF($C$4="All Departments",KPI_Calculations!Q12,INDEX(KPI_Calculations!Q6:Q11,MATCH($C$4,KPI_Calculations!A6:A11,0))),"0.00")&" / 5.0" -> Avg Perf Rating: 3.19 / 5.0 | L8: ="High Retention Risk Active: "&TEXT(IF($C$4="All Departments",Pivot_Analysis!B33,INDEX(Pivot_Analysis!B27:B32,MATCH($C$4,Pivot_Analysis!A27:A32,0))),"#,##0") -> High Retention Risk Active: 203
B10: Department Workforce, Attrition & Risk Scorecard (With Exception Highlighting) | J10: Executive Insights & Recommended Management Actions
B11: Department | C11: Active HC | D11: HC Variance | E11: FY25 Attrition % | F11: Cohort Attrition % | G11: Overtime % | H11: High Risk Staff | J11: 1. Overtime & Turnover Hotspot (Sales & Ops):
B12: =KPI_Calculations!A6 -> Engineering & Product | C12: =KPI_Calculations!D6 -> 366 | D12: =KPI_Calculations!E6 -> -14 | E12: =KPI_Calculations!N6 -> 0.083333333 | F12: =KPI_Calculations!I6 -> 0.21290323 | G12: =KPI_Calculations!R6 -> 0.2704918 | H12: =Pivot_Analysis!B27 -> 54 | J12: Enterprise Sales (52.2% OT, 15.1% FY25 attrition) and Customer Ops (51.2% OT, 37.1% cohort attrition) lead turnover. Action: Audit workload & fill -26 open roles.
B13: =KPI_Calculations!A7 -> Enterprise Sales | C13: =KPI_Calculations!D7 -> 201 | D13: =KPI_Calculations!E7 -> -14 | E13: =KPI_Calculations!N7 -> 0.15143603 | F13: =KPI_Calculations!I7 -> 0.33222591 | G13: =KPI_Calculations!R7 -> 0.52238806 | H13: =Pivot_Analysis!B28 -> 53 | J13: 2. External Agency ROI Deficit:
B14: =KPI_Calculations!A8 -> Customer Operations | C14: =KPI_Calculations!D8 -> 168 | D14: =KPI_Calculations!E8 -> -12 | E14: =KPI_Calculations!N8 -> 0.11538462 | F14: =KPI_Calculations!I8 -> 0.37078652 | G14: =KPI_Calculations!R8 -> 0.51190476 | H14: =Pivot_Analysis!B29 -> 44 | J14: External Agencies cost ₹145k/hire (2.4x weighted avg) yet show 40.4% cohort attrition & 21.7% first-year attrition vs. Employee Referrals (20.0% cohort attrition at ₹42k). Action: Shift budget to Referrals.
B15: =KPI_Calculations!A9 -> Growth Marketing | C15: =KPI_Calculations!D9 -> 119 | D15: =KPI_Calculations!E9 -> -6 | E15: =KPI_Calculations!N9 -> 0.14414414 | F15: =KPI_Calculations!I9 -> 0.31609195 | G15: =KPI_Calculations!R9 -> 0.31092437 | H15: =Pivot_Analysis!B30 -> 20 | J15: 3. Entry-Level (L1) Onboarding Risk:
B16: =KPI_Calculations!A10 -> Finance & Strategy | C16: =KPI_Calculations!D10 -> 96 | D16: =KPI_Calculations!E10 -> -4 | E16: =KPI_Calculations!N10 -> 0.055248619 | F16: =KPI_Calculations!I10 -> 0.24409449 | G16: =KPI_Calculations!R10 -> 0.29166667 | H16: =Pivot_Analysis!B31 -> 17 | J16: L1 Associates represent 50.2% of all historical exits (34.9% attrition), and 64.0% of all exits occur in Year 1. Action: Launch 30-60-90 day L1 structured check-ins.
B17: =KPI_Calculations!A11 -> People & Talent | C17: =KPI_Calculations!D11 -> 92 | D17: =KPI_Calculations!E11 -> -3 | E17: =KPI_Calculations!N11 -> 0.058479532 | F17: =KPI_Calculations!I11 -> 0.20689655 | G17: =KPI_Calculations!R11 -> 0.27173913 | H17: =Pivot_Analysis!B32 -> 15 | J17: 4. Hybrid Hub vs. Remote Retention:
B18: Organization Total / Avg | C18: =KPI_Calculations!D12 -> 1042 | D18: =KPI_Calculations!E12 -> -53 | E18: =KPI_Calculations!N12 -> 0.10381679 | F18: =KPI_Calculations!I12 -> 0.28137931 | G18: =KPI_Calculations!R12 -> 0.3646833 | H18: =Pivot_Analysis!B33 -> 203 | J18: Remote-India cohort attrition is 14.3% vs. Pune (31.5%) and Bengaluru (29.4%). Action: Review commute/flexibility policies in Pune & Bengaluru delivery centers.

Sheet KPI_Calculations
A1: WORKFORCE ANALYTICS FORMULA ENGINE (SUMIF/S, COUNTIF/S, AVERAGEIF/S, VLOOKUP, INDEX/MATCH, XLOOKUP, SUMPRODUCT)
A2: All summary tables dynamically calculate from 'Cleaned_Data' ($A$2:$AF$1451) and 'Employee_Lookups' and feed the Executive Dashboard.
A4: 1. Department-Wise Headcount, Attrition, Tenure, Overtime & Budget Variance
A5: Department | B5: Dept_Code | C5: Approved_HC_Target | D5: Active_Headcount | E5: HC_Target_Variance | F5: Total_Historical_Hires | G5: Total_Historical_Exits | H5: Voluntary_Exits | I5: Cumulative_Cohort_Attrition_% | J5: FY2025_Starting_HC | K5: FY2025_Hires | L5: FY2025_Exits | M5: FY2025_Avg_HC | N5: FY2025_Annual_Attrition_% | O5: Avg_Tenure_Active_Yrs | P5: Avg_Active_Salary_INR | Q5: Avg_Perf_Rating | R5: Active_Overtime_%
A6: Engineering & Product | B6: DEP-ENG | C6: =VLOOKUP(B6,Employee_Lookups!$A$4:$G$9,5,FALSE()) -> 380 | D6: =COUNTIFS(Cleaned_Data!$D$2:$D$1451,A6,Cleaned_Data!$K$2:$K$1451,"Active") -> 366 | E6: =D6-C6 -> -14 | F6: =COUNTIF(Cleaned_Data!$D$2:$D$1451,A6) -> 465 | G6: =COUNTIFS(Cleaned_Data!$D$2:$D$1451,A6,Cleaned_Data!$K$2:$K$1451,"<>Active") -> 99 | H6: =COUNTIFS(Cleaned_Data!$D$2:$D$1451,A6,Cleaned_Data!$K$2:$K$1451,"Voluntary Exit") -> 63 | I6: =IFERROR(G6/F6,0) -> 0.21290323 | J6: =COUNTIFS(Cleaned_Data!$D$2:$D$1451,A6,Cleaned_Data!$AB$2:$AB$1451,"<=2024")-COUNTIFS(Cleaned_Data!$D$2:$D$1451,A6,Cleaned_Data!$AB$2:$AB$1451,"<=2024",Cleaned_Data!$AC$2:$AC$1451,"<=2024",Cleaned_Data!$AC$2:$AC$1451,">0") -> 330 | K6: =COUNTIFS(Cleaned_Data!$D$2:$D$1451,A6,Cleaned_Data!$AB$2:$AB$1451,2025) -> 65 | L6: =COUNTIFS(Cleaned_Data!$D$2:$D$1451,A6,Cleaned_Data!$AC$2:$AC$1451,2025) -> 29 | M6: =(J6+D6)/2 -> 348 | N6: =IFERROR(L6/M6,0) -> 0.083333333 | O6: =AVERAGEIFS(Cleaned_Data!$AD$2:$AD$1451,Cleaned_Data!$D$2:$D$1451,A6,Cleaned_Data!$K$2:$K$1451,"Active") -> 2.7999454 | P6: =AVERAGEIFS(Cleaned_Data!$O$2:$O$1451,Cleaned_Data!$D$2:$D$1451,A6,Cleaned_Data!$K$2:$K$1451,"Active") -> 1297612 | Q6: =AVERAGEIFS(Cleaned_Data!$P$2:$P$1451,Cleaned_Data!$D$2:$D$1451,A6,Cleaned_Data!$P$2:$P$1451,">0") -> 3.2171053 | R6: =IFERROR(COUNTIFS(Cleaned_Data!$D$2:$D$1451,A6,Cleaned_Data!$K$2:$K$1451,"Active",Cleaned_Data!$Q$2:$Q$1451,"Yes")/D6,0) -> 0.2704918
A7: Enterprise Sales | B7: DEP-SAL | C7: =VLOOKUP(B7,Employee_Lookups!$A$4:$G$9,5,FALSE()) -> 215 | D7: =COUNTIFS(Cleaned_Data!$D$2:$D$1451,A7,Cleaned_Data!$K$2:$K$1451,"Active") -> 201 | E7: =D7-C7 -> -14 | F7: =COUNTIF(Cleaned_Data!$D$2:$D$1451,A7) -> 301 | G7: =COUNTIFS(Cleaned_Data!$D$2:$D$1451,A7,Cleaned_Data!$K$2:$K$1451,"<>Active") -> 100 | H7: =COUNTIFS(Cleaned_Data!$D$2:$D$1451,A7,Cleaned_Data!$K$2:$K$1451,"Voluntary Exit") -> 67 | I7: =IFERROR(G7/F7,0) -> 0.33222591 | J7: =COUNTIFS(Cleaned_Data!$D$2:$D$1451,A7,Cleaned_Data!$AB$2:$AB$1451,"<=2024")-COUNTIFS(Cleaned_Data!$D$2:$D$1451,A7,Cleaned_Data!$AB$2:$AB$1451,"<=2024",Cleaned_Data!$AC$2:$AC$1451,"<=2024",Cleaned_Data!$AC$2:$AC$1451,">0") -> 182 | K7: =COUNTIFS(Cleaned_Data!$D$2:$D$1451,A7,Cleaned_Data!$AB$2:$AB$1451,2025) -> 48 | L7: =COUNTIFS(Cleaned_Data!$D$2:$D$1451,A7,Cleaned_Data!$AC$2:$AC$1451,2025) -> 29 | M7: =(J7+D7)/2 -> 191.5 | N7: =IFERROR(L7/M7,0) -> 0.15143603 | O7: =AVERAGEIFS(Cleaned_Data!$AD$2:$AD$1451,Cleaned_Data!$D$2:$D$1451,A7,Cleaned_Data!$K$2:$K$1451,"Active") -> 2.4998507 | P7: =AVERAGEIFS(Cleaned_Data!$O$2:$O$1451,Cleaned_Data!$D$2:$D$1451,A7,Cleaned_Data!$K$2:$K$1451,"Active") -> 1294432.8 | Q7: =AVERAGEIFS(Cleaned_Data!$P$2:$P$1451,Cleaned_Data!$D$2:$D$1451,A7,Cleaned_Data!$P$2:$P$1451,">0") -> 3.1190476 | R7: =IFERROR(COUNTIFS(Cleaned_Data!$D$2:$D$1451,A7,Cleaned_Data!$K$2:$K$1451,"Active",Cleaned_Data!$Q$2:$Q$1451,"Yes")/D7,0) -> 0.52238806
A8: Customer Operations | B8: DEP-OPS | C8: =VLOOKUP(B8,Employee_Lookups!$A$4:$G$9,5,FALSE()) -> 180 | D8: =COUNTIFS(Cleaned_Data!$D$2:$D$1451,A8,Cleaned_Data!$K$2:$K$1451,"Active") -> 168 | E8: =D8-C8 -> -12 | F8: =COUNTIF(Cleaned_Data!$D$2:$D$1451,A8) -> 267 | G8: =COUNTIFS(Cleaned_Data!$D$2:$D$1451,A8,Cleaned_Data!$K$2:$K$1451,"<>Active") -> 99 | H8: =COUNTIFS(Cleaned_Data!$D$2:$D$1451,A8,Cleaned_Data!$K$2:$K$1451,"Voluntary Exit") -> 61 | I8: =IFERROR(G8/F8,0) -> 0.37078652 | J8: =COUNTIFS(Cleaned_Data!$D$2:$D$1451,A8,Cleaned_Data!$AB$2:$AB$1451,"<=2024")-COUNTIFS(Cleaned_Data!$D$2:$D$1451,A8,Cleaned_Data!$AB$2:$AB$1451,"<=2024",Cleaned_Data!$AC$2:$AC$1451,"<=2024",Cleaned_Data!$AC$2:$AC$1451,">0") -> 144 | K8: =COUNTIFS(Cleaned_Data!$D$2:$D$1451,A8,Cleaned_Data!$AB$2:$AB$1451,2025) -> 42 | L8: =COUNTIFS(Cleaned_Data!$D$2:$D$1451,A8,Cleaned_Data!$AC$2:$AC$1451,2025) -> 18 | M8: =(J8+D8)/2 -> 156 | N8: =IFERROR(L8/M8,0) -> 0.11538462 | O8: =AVERAGEIFS(Cleaned_Data!$AD$2:$AD$1451,Cleaned_Data!$D$2:$D$1451,A8,Cleaned_Data!$K$2:$K$1451,"Active") -> 2.5744643 | P8: =AVERAGEIFS(Cleaned_Data!$O$2:$O$1451,Cleaned_Data!$D$2:$D$1451,A8,Cleaned_Data!$K$2:$K$1451,"Active") -> 1383113.1 | Q8: =AVERAGEIFS(Cleaned_Data!$P$2:$P$1451,Cleaned_Data!$D$2:$D$1451,A8,Cleaned_Data!$P$2:$P$1451,">0") -> 3.1030534 | R8: =IFERROR(COUNTIFS(Cleaned_Data!$D$2:$D$1451,A8,Cleaned_Data!$K$2:$K$1451,"Active",Cleaned_Data!$Q$2:$Q$1451,"Yes")/D8,0) -> 0.51190476
A9: Growth Marketing | B9: DEP-MKT | C9: =VLOOKUP(B9,Employee_Lookups!$A$4:$G$9,5,FALSE()) -> 125 | D9: =COUNTIFS(Cleaned_Data!$D$2:$D$1451,A9,Cleaned_Data!$K$2:$K$1451,"Active") -> 119 | E9: =D9-C9 -> -6 | F9: =COUNTIF(Cleaned_Data!$D$2:$D$1451,A9) -> 174 | G9: =COUNTIFS(Cleaned_Data!$D$2:$D$1451,A9,Cleaned_Data!$K$2:$K$1451,"<>Active") -> 55 | H9: =COUNTIFS(Cleaned_Data!$D$2:$D$1451,A9,Cleaned_Data!$K$2:$K$1451,"Voluntary Exit") -> 37 | I9: =IFERROR(G9/F9,0) -> 0.31609195 | J9: =COUNTIFS(Cleaned_Data!$D$2:$D$1451,A9,Cleaned_Data!$AB$2:$AB$1451,"<=2024")-COUNTIFS(Cleaned_Data!$D$2:$D$1451,A9,Cleaned_Data!$AB$2:$AB$1451,"<=2024",Cleaned_Data!$AC$2:$AC$1451,"<=2024",Cleaned_Data!$AC$2:$AC$1451,">0") -> 103 | K9: =COUNTIFS(Cleaned_Data!$D$2:$D$1451,A9,Cleaned_Data!$AB$2:$AB$1451,2025) -> 32 | L9: =COUNTIFS(Cleaned_Data!$D$2:$D$1451,A9,Cleaned_Data!$AC$2:$AC$1451,2025) -> 16 | M9: =(J9+D9)/2 -> 111 | N9: =IFERROR(L9/M9,0) -> 0.14414414 | O9: =AVERAGEIFS(Cleaned_Data!$AD$2:$AD$1451,Cleaned_Data!$D$2:$D$1451,A9,Cleaned_Data!$K$2:$K$1451,"Active") -> 2.3438655 | P9: =AVERAGEIFS(Cleaned_Data!$O$2:$O$1451,Cleaned_Data!$D$2:$D$1451,A9,Cleaned_Data!$K$2:$K$1451,"Active") -> 1261159.7 | Q9: =AVERAGEIFS(Cleaned_Data!$P$2:$P$1451,Cleaned_Data!$D$2:$D$1451,A9,Cleaned_Data!$P$2:$P$1451,">0") -> 3.2559524 | R9: =IFERROR(COUNTIFS(Cleaned_Data!$D$2:$D$1451,A9,Cleaned_Data!$K$2:$K$1451,"Active",Cleaned_Data!$Q$2:$Q$1451,"Yes")/D9,0) -> 0.31092437
A10: Finance & Strategy | B10: DEP-FIN | C10: =VLOOKUP(B10,Employee_Lookups!$A$4:$G$9,5,FALSE()) -> 100 | D10: =COUNTIFS(Cleaned_Data!$D$2:$D$1451,A10,Cleaned_Data!$K$2:$K$1451,"Active") -> 96 | E10: =D10-C10 -> -4 | F10: =COUNTIF(Cleaned_Data!$D$2:$D$1451,A10) -> 127 | G10: =COUNTIFS(Cleaned_Data!$D$2:$D$1451,A10,Cleaned_Data!$K$2:$K$1451,"<>Active") -> 31 | H10: =COUNTIFS(Cleaned_Data!$D$2:$D$1451,A10,Cleaned_Data!$K$2:$K$1451,"Voluntary Exit") -> 21 | I10: =IFERROR(G10/F10,0) -> 0.24409449 | J10: =COUNTIFS(Cleaned_Data!$D$2:$D$1451,A10,Cleaned_Data!$AB$2:$AB$1451,"<=2024")-COUNTIFS(Cleaned_Data!$D$2:$D$1451,A10,Cleaned_Data!$AB$2:$AB$1451,"<=2024",Cleaned_Data!$AC$2:$AC$1451,"<=2024",Cleaned_Data!$AC$2:$AC$1451,">0") -> 85 | K10: =COUNTIFS(Cleaned_Data!$D$2:$D$1451,A10,Cleaned_Data!$AB$2:$AB$1451,2025) -> 16 | L10: =COUNTIFS(Cleaned_Data!$D$2:$D$1451,A10,Cleaned_Data!$AC$2:$AC$1451,2025) -> 5 | M10: =(J10+D10)/2 -> 90.5 | N10: =IFERROR(L10/M10,0) -> 0.055248619 | O10: =AVERAGEIFS(Cleaned_Data!$AD$2:$AD$1451,Cleaned_Data!$D$2:$D$1451,A10,Cleaned_Data!$K$2:$K$1451,"Active") -> 3.2403125 | P10: =AVERAGEIFS(Cleaned_Data!$O$2:$O$1451,Cleaned_Data!$D$2:$D$1451,A10,Cleaned_Data!$K$2:$K$1451,"Active") -> 1176114.6 | Q10: =AVERAGEIFS(Cleaned_Data!$P$2:$P$1451,Cleaned_Data!$D$2:$D$1451,A10,Cleaned_Data!$P$2:$P$1451,">0") -> 3.2777778 | R10: =IFERROR(COUNTIFS(Cleaned_Data!$D$2:$D$1451,A10,Cleaned_Data!$K$2:$K$1451,"Active",Cleaned_Data!$Q$2:$Q$1451,"Yes")/D10,0) -> 0.29166667
A11: People & Talent | B11: DEP-HR | C11: =VLOOKUP(B11,Employee_Lookups!$A$4:$G$9,5,FALSE()) -> 95 | D11: =COUNTIFS(Cleaned_Data!$D$2:$D$1451,A11,Cleaned_Data!$K$2:$K$1451,"Active") -> 92 | E11: =D11-C11 -> -3 | F11: =COUNTIF(Cleaned_Data!$D$2:$D$1451,A11) -> 116 | G11: =COUNTIFS(Cleaned_Data!$D$2:$D$1451,A11,Cleaned_Data!$K$2:$K$1451,"<>Active") -> 24 | H11: =COUNTIFS(Cleaned_Data!$D$2:$D$1451,A11,Cleaned_Data!$K$2:$K$1451,"Voluntary Exit") -> 16 | I11: =IFERROR(G11/F11,0) -> 0.20689655 | J11: =COUNTIFS(Cleaned_Data!$D$2:$D$1451,A11,Cleaned_Data!$AB$2:$AB$1451,"<=2024")-COUNTIFS(Cleaned_Data!$D$2:$D$1451,A11,Cleaned_Data!$AB$2:$AB$1451,"<=2024",Cleaned_Data!$AC$2:$AC$1451,"<=2024",Cleaned_Data!$AC$2:$AC$1451,">0") -> 79 | K11: =COUNTIFS(Cleaned_Data!$D$2:$D$1451,A11,Cleaned_Data!$AB$2:$AB$1451,2025) -> 18 | L11: =COUNTIFS(Cleaned_Data!$D$2:$D$1451,A11,Cleaned_Data!$AC$2:$AC$1451,2025) -> 5 | M11: =(J11+D11)/2 -> 85.5 | N11: =IFERROR(L11/M11,0) -> 0.058479532 | O11: =AVERAGEIFS(Cleaned_Data!$AD$2:$AD$1451,Cleaned_Data!$D$2:$D$1451,A11,Cleaned_Data!$K$2:$K$1451,"Active") -> 2.8375 | P11: =AVERAGEIFS(Cleaned_Data!$O$2:$O$1451,Cleaned_Data!$D$2:$D$1451,A11,Cleaned_Data!$K$2:$K$1451,"Active") -> 1453184.8 | Q11: =AVERAGEIFS(Cleaned_Data!$P$2:$P$1451,Cleaned_Data!$D$2:$D$1451,A11,Cleaned_Data!$P$2:$P$1451,">0") -> 3.2280702 | R11: =IFERROR(COUNTIFS(Cleaned_Data!$D$2:$D$1451,A11,Cleaned_Data!$K$2:$K$1451,"Active",Cleaned_Data!$Q$2:$Q$1451,"Yes")/D11,0) -> 0.27173913
A12: Total / Organization Benchmark | B12: ALL-ORG | C12: =SUM(C6:C11) -> 1095 | D12: =SUM(D6:D11) -> 1042 | E12: =D12-C12 -> -53 | F12: =SUM(F6:F11) -> 1450 | G12: =SUM(G6:G11) -> 408 | H12: =SUM(H6:H11) -> 265 | I12: =IFERROR(G12/F12,0) -> 0.28137931 | J12: =SUM(J6:J11) -> 923 | K12: =SUM(K6:K11) -> 221 | L12: =SUM(L6:L11) -> 102 | M12: =(J12+D12)/2 -> 982.5 | N12: =IFERROR(L12/M12,0) -> 0.10381679 | O12: =SUMPRODUCT(D6:D11,O6:O11)/D12 -> 2.6975048 | P12: =SUMPRODUCT(D6:D11,P6:P11)/D12 -> 1309163.1 | Q12: =AVERAGEIF(Cleaned_Data!$P$2:$P$1451,">0") -> 3.1866197 | R12: =SUMPRODUCT(D6:D11,R6:R11)/D12 -> 0.3646833
A15: 2. Historical Workforce Growth, Hiring Velocity & Annualized Attrition Trend (2019–2025)
A16: Calendar_Year | B16: Starting_Headcount | C16: New_Hires | D16: Total_Exits | E16: Net_Headcount_Change | F16: Ending_Headcount | G16: Average_Headcount | H16: Annual_Attrition_Rate_%
A17: 2019 | B17: 0 | C17: =COUNTIF(Cleaned_Data!$AB$2:$AB$1451,A17) -> 87 | D17: =COUNTIF(Cleaned_Data!$AC$2:$AC$1451,A17) -> 9 | E17: =C17-D17 -> 78 | F17: =B17+E17 -> 78 | G17: =(B17+F17)/2 -> 39 | H17: =IFERROR(D17/G17,0) -> 0.23076923
A18: 2020 | B18: =F17 -> 78 | C18: =COUNTIF(Cleaned_Data!$AB$2:$AB$1451,A18) -> 116 | D18: =COUNTIF(Cleaned_Data!$AC$2:$AC$1451,A18) -> 22 | E18: =C18-D18 -> 94 | F18: =B18+E18 -> 172 | G18: =(B18+F18)/2 -> 125 | H18: =IFERROR(D18/G18,0) -> 0.176
A19: 2021 | B19: =F18 -> 172 | C19: =COUNTIF(Cleaned_Data!$AB$2:$AB$1451,A19) -> 197 | D19: =COUNTIF(Cleaned_Data!$AC$2:$AC$1451,A19) -> 37 | E19: =C19-D19 -> 160 | F19: =B19+E19 -> 332 | G19: =(B19+F19)/2 -> 252 | H19: =IFERROR(D19/G19,0) -> 0.1468254
A20: 2022 | B20: =F19 -> 332 | C20: =COUNTIF(Cleaned_Data!$AB$2:$AB$1451,A20) -> 299 | D20: =COUNTIF(Cleaned_Data!$AC$2:$AC$1451,A20) -> 72 | E20: =C20-D20 -> 227 | F20: =B20+E20 -> 559 | G20: =(B20+F20)/2 -> 445.5 | H20: =IFERROR(D20/G20,0) -> 0.16161616
A21: 2023 | B21: =F20 -> 559 | C21: =COUNTIF(Cleaned_Data!$AB$2:$AB$1451,A21) -> 268 | D21: =COUNTIF(Cleaned_Data!$AC$2:$AC$1451,A21) -> 82 | E21: =C21-D21 -> 186 | F21: =B21+E21 -> 745 | G21: =(B21+F21)/2 -> 652 | H21: =IFERROR(D21/G21,0) -> 0.12576687
A22: 2024 | B22: =F21 -> 745 | C22: =COUNTIF(Cleaned_Data!$AB$2:$AB$1451,A22) -> 262 | D22: =COUNTIF(Cleaned_Data!$AC$2:$AC$1451,A22) -> 84 | E22: =C22-D22 -> 178 | F22: =B22+E22 -> 923 | G22: =(B22+F22)/2 -> 834 | H22: =IFERROR(D22/G22,0) -> 0.10071942
A23: 2025 | B23: =F22 -> 923 | C23: =COUNTIF(Cleaned_Data!$AB$2:$AB$1451,A23) -> 221 | D23: =COUNTIF(Cleaned_Data!$AC$2:$AC$1451,A23) -> 102 | E23: =C23-D23 -> 119 | F23: =B23+E23 -> 1042 | G23: =(B23+F23)/2 -> 982.5 | H23: =IFERROR(D23/G23,0) -> 0.10381679
A26: 3. Job Level & Compensation Band Distribution, Attrition & Overtime Analysis
A27: Job_Level | B27: Level_Category | C27: Salary_Band | D27: Active_Headcount | E27: Historical_Exits | F27: Cohort_Attrition_% | G27: Avg_Active_Salary_INR | H27: Band_Midpoint_INR | I27: Avg_Compa_Ratio | J27: Active_Overtime_%
A28: L1 | B28: =INDEX(Employee_Lookups!$B$13:$B$17,MATCH(A28,Employee_Lookups!$A$13:$A$17,0)) -> Associate / Analyst | C28: =INDEX(Employee_Lookups!$C$13:$C$17,MATCH(A28,Employee_Lookups!$A$13:$A$17,0)) -> Band A (Entry) | D28: =COUNTIFS(Cleaned_Data!$F$2:$F$1451,A28,Cleaned_Data!$K$2:$K$1451,"Active") -> 382 | E28: =COUNTIFS(Cleaned_Data!$F$2:$F$1451,A28,Cleaned_Data!$K$2:$K$1451,"<>Active") -> 205 | F28: =IFERROR(E28/(D28+E28),0) -> 0.34923339 | G28: =AVERAGEIFS(Cleaned_Data!$O$2:$O$1451,Cleaned_Data!$F$2:$F$1451,A28,Cleaned_Data!$K$2:$K$1451,"Active") -> 701335.08 | H28: =VLOOKUP(A28,Employee_Lookups!$A$13:$G$17,5,FALSE()) -> 700000 | I28: =IFERROR(G28/H28,0) -> 1.0019073 | J28: =IFERROR(COUNTIFS(Cleaned_Data!$F$2:$F$1451,A28,Cleaned_Data!$K$2:$K$1451,"Active",Cleaned_Data!$Q$2:$Q$1451,"Yes")/D28,0) -> 0.36387435
A29: L2 | B29: =INDEX(Employee_Lookups!$B$13:$B$17,MATCH(A29,Employee_Lookups!$A$13:$A$17,0)) -> Specialist / Sr. Analyst | C29: =INDEX(Employee_Lookups!$C$13:$C$17,MATCH(A29,Employee_Lookups!$A$13:$A$17,0)) -> Band B (Mid) | D29: =COUNTIFS(Cleaned_Data!$F$2:$F$1451,A29,Cleaned_Data!$K$2:$K$1451,"Active") -> 378 | E29: =COUNTIFS(Cleaned_Data!$F$2:$F$1451,A29,Cleaned_Data!$K$2:$K$1451,"<>Active") -> 124 | F29: =IFERROR(E29/(D29+E29),0) -> 0.24701195 | G29: =AVERAGEIFS(Cleaned_Data!$O$2:$O$1451,Cleaned_Data!$F$2:$F$1451,A29,Cleaned_Data!$K$2:$K$1451,"Active") -> 1111518.5 | H29: =VLOOKUP(A29,Employee_Lookups!$A$13:$G$17,5,FALSE()) -> 1100000 | I29: =IFERROR(G29/H29,0) -> 1.0104714 | J29: =IFERROR(COUNTIFS(Cleaned_Data!$F$2:$F$1451,A29,Cleaned_Data!$K$2:$K$1451,"Active",Cleaned_Data!$Q$2:$Q$1451,"Yes")/D29,0) -> 0.38095238
A30: L3 | B30: =INDEX(Employee_Lookups!$B$13:$B$17,MATCH(A30,Employee_Lookups!$A$13:$A$17,0)) -> Lead / Manager | C30: =INDEX(Employee_Lookups!$C$13:$C$17,MATCH(A30,Employee_Lookups!$A$13:$A$17,0)) -> Band C (Senior) | D30: =COUNTIFS(Cleaned_Data!$F$2:$F$1451,A30,Cleaned_Data!$K$2:$K$1451,"Active") -> 155 | E30: =COUNTIFS(Cleaned_Data!$F$2:$F$1451,A30,Cleaned_Data!$K$2:$K$1451,"<>Active") -> 52 | F30: =IFERROR(E30/(D30+E30),0) -> 0.25120773 | G30: =AVERAGEIFS(Cleaned_Data!$O$2:$O$1451,Cleaned_Data!$F$2:$F$1451,A30,Cleaned_Data!$K$2:$K$1451,"Active") -> 1729412.9 | H30: =VLOOKUP(A30,Employee_Lookups!$A$13:$G$17,5,FALSE()) -> 1725000 | I30: =IFERROR(G30/H30,0) -> 1.0025582 | J30: =IFERROR(COUNTIFS(Cleaned_Data!$F$2:$F$1451,A30,Cleaned_Data!$K$2:$K$1451,"Active",Cleaned_Data!$Q$2:$Q$1451,"Yes")/D30,0) -> 0.39354839
A31: L4 | B31: =INDEX(Employee_Lookups!$B$13:$B$17,MATCH(A31,Employee_Lookups!$A$13:$A$17,0)) -> Director / Principal | C31: =INDEX(Employee_Lookups!$C$13:$C$17,MATCH(A31,Employee_Lookups!$A$13:$A$17,0)) -> Band D (Leadership) | D31: =COUNTIFS(Cleaned_Data!$F$2:$F$1451,A31,Cleaned_Data!$K$2:$K$1451,"Active") -> 90 | E31: =COUNTIFS(Cleaned_Data!$F$2:$F$1451,A31,Cleaned_Data!$K$2:$K$1451,"<>Active") -> 17 | F31: =IFERROR(E31/(D31+E31),0) -> 0.1588785 | G31: =AVERAGEIFS(Cleaned_Data!$O$2:$O$1451,Cleaned_Data!$F$2:$F$1451,A31,Cleaned_Data!$K$2:$K$1451,"Active") -> 2793100 | H31: =VLOOKUP(A31,Employee_Lookups!$A$13:$G$17,5,FALSE()) -> 2750000 | I31: =IFERROR(G31/H31,0) -> 1.0156727 | J31: =IFERROR(COUNTIFS(Cleaned_Data!$F$2:$F$1451,A31,Cleaned_Data!$K$2:$K$1451,"Active",Cleaned_Data!$Q$2:$Q$1451,"Yes")/D31,0) -> 0.28888889
A32: L5 | B32: =INDEX(Employee_Lookups!$B$13:$B$17,MATCH(A32,Employee_Lookups!$A$13:$A$17,0)) -> VP / Executive | C32: =INDEX(Employee_Lookups!$C$13:$C$17,MATCH(A32,Employee_Lookups!$A$13:$A$17,0)) -> Band E (Executive) | D32: =COUNTIFS(Cleaned_Data!$F$2:$F$1451,A32,Cleaned_Data!$K$2:$K$1451,"Active") -> 37 | E32: =COUNTIFS(Cleaned_Data!$F$2:$F$1451,A32,Cleaned_Data!$K$2:$K$1451,"<>Active") -> 10 | F32: =IFERROR(E32/(D32+E32),0) -> 0.21276596 | G32: =AVERAGEIFS(Cleaned_Data!$O$2:$O$1451,Cleaned_Data!$F$2:$F$1451,A32,Cleaned_Data!$K$2:$K$1451,"Active") -> 4233675.7 | H32: =VLOOKUP(A32,Employee_Lookups!$A$13:$G$17,5,FALSE()) -> 4300000 | I32: =IFERROR(G32/H32,0) -> 0.98457574 | J32: =IFERROR(COUNTIFS(Cleaned_Data!$F$2:$F$1451,A32,Cleaned_Data!$K$2:$K$1451,"Active",Cleaned_Data!$Q$2:$Q$1451,"Yes")/D32,0) -> 0.27027027
A35: 4. Recruitment Source ROI, First-Year Attrition & Weighted Cost-Per-Hire (SUMPRODUCT)
A36: Recruitment_Source | B36: Total_Hires | C36: Share_of_Hires_% | D36: Active_Retained | E36: Total_Exits | F36: First_Year_Exits (<1 Yr) | G36: Overall_Source_Attrition_% | H36: First_Year_Attrition_% | I36: Avg_Perf_Rating | J36: Std_Cost_Per_Hire_INR
A37: Campus Recruitment | B37: =COUNTIF(Cleaned_Data!$N$2:$N$1451,A37) -> 243 | C37: =B37/$B$42 -> 0.16758621 | D37: =COUNTIFS(Cleaned_Data!$N$2:$N$1451,A37,Cleaned_Data!$K$2:$K$1451,"Active") -> 181 | E37: =COUNTIFS(Cleaned_Data!$N$2:$N$1451,A37,Cleaned_Data!$K$2:$K$1451,"<>Active") -> 62 | F37: =COUNTIFS(Cleaned_Data!$N$2:$N$1451,A37,Cleaned_Data!$K$2:$K$1451,"<>Active",Cleaned_Data!$AD$2:$AD$1451,"<1") -> 32 | G37: =IFERROR(E37/B37,0) -> 0.25514403 | H37: =IFERROR(F37/B37,0) -> 0.13168724 | I37: =AVERAGEIFS(Cleaned_Data!$P$2:$P$1451,Cleaned_Data!$N$2:$N$1451,A37,Cleaned_Data!$P$2:$P$1451,">0") -> 3.1344538 | J37: =VLOOKUP(A37,Employee_Lookups!$A$21:$C$25,2,FALSE()) -> 35000
A38: Company Career Portal | B38: =COUNTIF(Cleaned_Data!$N$2:$N$1451,A38) -> 240 | C38: =B38/$B$42 -> 0.16551724 | D38: =COUNTIFS(Cleaned_Data!$N$2:$N$1451,A38,Cleaned_Data!$K$2:$K$1451,"Active") -> 177 | E38: =COUNTIFS(Cleaned_Data!$N$2:$N$1451,A38,Cleaned_Data!$K$2:$K$1451,"<>Active") -> 63 | F38: =COUNTIFS(Cleaned_Data!$N$2:$N$1451,A38,Cleaned_Data!$K$2:$K$1451,"<>Active",Cleaned_Data!$AD$2:$AD$1451,"<1") -> 45 | G38: =IFERROR(E38/B38,0) -> 0.2625 | H38: =IFERROR(F38/B38,0) -> 0.1875 | I38: =AVERAGEIFS(Cleaned_Data!$P$2:$P$1451,Cleaned_Data!$N$2:$N$1451,A38,Cleaned_Data!$P$2:$P$1451,">0") -> 3.2863248 | J38: =VLOOKUP(A38,Employee_Lookups!$A$21:$C$25,2,FALSE()) -> 22000
A39: Employee Referral | B39: =COUNTIF(Cleaned_Data!$N$2:$N$1451,A39) -> 310 | C39: =B39/$B$42 -> 0.2137931 | D39: =COUNTIFS(Cleaned_Data!$N$2:$N$1451,A39,Cleaned_Data!$K$2:$K$1451,"Active") -> 248 | E39: =COUNTIFS(Cleaned_Data!$N$2:$N$1451,A39,Cleaned_Data!$K$2:$K$1451,"<>Active") -> 62 | F39: =COUNTIFS(Cleaned_Data!$N$2:$N$1451,A39,Cleaned_Data!$K$2:$K$1451,"<>Active",Cleaned_Data!$AD$2:$AD$1451,"<1") -> 46 | G39: =IFERROR(E39/B39,0) -> 0.2 | H39: =IFERROR(F39/B39,0) -> 0.1483871 | I39: =AVERAGEIFS(Cleaned_Data!$P$2:$P$1451,Cleaned_Data!$N$2:$N$1451,A39,Cleaned_Data!$P$2:$P$1451,">0") -> 3.1901639 | J39: =VLOOKUP(A39,Employee_Lookups!$A$21:$C$25,2,FALSE()) -> 42000
A40: External Agency | B40: =COUNTIF(Cleaned_Data!$N$2:$N$1451,A40) -> 198 | C40: =B40/$B$42 -> 0.13655172 | D40: =COUNTIFS(Cleaned_Data!$N$2:$N$1451,A40,Cleaned_Data!$K$2:$K$1451,"Active") -> 118 | E40: =COUNTIFS(Cleaned_Data!$N$2:$N$1451,A40,Cleaned_Data!$K$2:$K$1451,"<>Active") -> 80 | F40: =COUNTIFS(Cleaned_Data!$N$2:$N$1451,A40,Cleaned_Data!$K$2:$K$1451,"<>Active",Cleaned_Data!$AD$2:$AD$1451,"<1") -> 43 | G40: =IFERROR(E40/B40,0) -> 0.4040404 | H40: =IFERROR(F40/B40,0) -> 0.21717172 | I40: =AVERAGEIFS(Cleaned_Data!$P$2:$P$1451,Cleaned_Data!$N$2:$N$1451,A40,Cleaned_Data!$P$2:$P$1451,">0") -> 3.1435897 | J40: =VLOOKUP(A40,Employee_Lookups!$A$21:$C$25,2,FALSE()) -> 145000
A41: LinkedIn Sourcing | B41: =COUNTIF(Cleaned_Data!$N$2:$N$1451,A41) -> 459 | C41: =B41/$B$42 -> 0.31655172 | D41: =COUNTIFS(Cleaned_Data!$N$2:$N$1451,A41,Cleaned_Data!$K$2:$K$1451,"Active") -> 318 | E41: =COUNTIFS(Cleaned_Data!$N$2:$N$1451,A41,Cleaned_Data!$K$2:$K$1451,"<>Active") -> 141 | F41: =COUNTIFS(Cleaned_Data!$N$2:$N$1451,A41,Cleaned_Data!$K$2:$K$1451,"<>Active",Cleaned_Data!$AD$2:$AD$1451,"<1") -> 95 | G41: =IFERROR(E41/B41,0) -> 0.30718954 | H41: =IFERROR(F41/B41,0) -> 0.20697168 | I41: =AVERAGEIFS(Cleaned_Data!$P$2:$P$1451,Cleaned_Data!$N$2:$N$1451,A41,Cleaned_Data!$P$2:$P$1451,">0") -> 3.1785714 | J41: =VLOOKUP(A41,Employee_Lookups!$A$21:$C$25,2,FALSE()) -> 68000
A42: Total / Weighted Portfolio | B42: =SUM(B37:B41) -> 1450 | C42: =SUM(C37:C41) -> 1 | D42: =SUM(D37:D41) -> 1042 | E42: =SUM(E37:E41) -> 408 | F42: =SUM(F37:F41) -> 261 | G42: =IFERROR(E42/B42,0) -> 0.28137931 | H42: =IFERROR(F42/B42,0) -> 0.18 | I42: =SUMPRODUCT(B37:B41,I37:I41)/B42 -> 3.1867145 | J42: =SUMPRODUCT(B37:B41,J37:J41)/B42 -> 59811.724
A45: 5. Location & Work Mode Headcount, Attrition & Payroll Distribution
A46: Location | B46: Work_Mode | C46: Active_Headcount | D46: Share_of_Active_HC_% | E46: Total_Exits | F46: Cohort_Attrition_% | G46: Active_Payroll_INR (SUMIFS)
A47: Bengaluru | B47: Hybrid | C47: =COUNTIFS(Cleaned_Data!$H$2:$H$1451,A47,Cleaned_Data!$K$2:$K$1451,"Active") -> 426 | D47: =C47/$C$52 -> 0.40882917 | E47: =COUNTIFS(Cleaned_Data!$H$2:$H$1451,A47,Cleaned_Data!$K$2:$K$1451,"<>Active") -> 177 | F47: =IFERROR(E47/(C47+E47),0) -> 0.29353234 | G47: =SUMIFS(Cleaned_Data!$O$2:$O$1451,Cleaned_Data!$H$2:$H$1451,A47,Cleaned_Data!$K$2:$K$1451,"Active") -> 565018000
A48: Pune | B48: Hybrid | C48: =COUNTIFS(Cleaned_Data!$H$2:$H$1451,A48,Cleaned_Data!$K$2:$K$1451,"Active") -> 261 | D48: =C48/$C$52 -> 0.25047985 | E48: =COUNTIFS(Cleaned_Data!$H$2:$H$1451,A48,Cleaned_Data!$K$2:$K$1451,"<>Active") -> 120 | F48: =IFERROR(E48/(C48+E48),0) -> 0.31496063 | G48: =SUMIFS(Cleaned_Data!$O$2:$O$1451,Cleaned_Data!$H$2:$H$1451,A48,Cleaned_Data!$K$2:$K$1451,"Active") -> 343335000
A49: Hyderabad | B49: On-Site | C49: =COUNTIFS(Cleaned_Data!$H$2:$H$1451,A49,Cleaned_Data!$K$2:$K$1451,"Active") -> 195 | D49: =C49/$C$52 -> 0.18714012 | E49: =COUNTIFS(Cleaned_Data!$H$2:$H$1451,A49,Cleaned_Data!$K$2:$K$1451,"<>Active") -> 68 | F49: =IFERROR(E49/(C49+E49),0) -> 0.25855513 | G49: =SUMIFS(Cleaned_Data!$O$2:$O$1451,Cleaned_Data!$H$2:$H$1451,A49,Cleaned_Data!$K$2:$K$1451,"Active") -> 257750000
...

Sheet Pivot_Analysis
A1: MULTI-DIMENSIONAL CROSS-TAB ANALYSIS (Formula-Driven Pivot Matrices + Native PivotTable Staging)
A2: Note: Because Python XML builders cannot compile binary PivotCaches natively, these cross-tabs use live COUNTIFS/AVERAGEIFS formulas. Native PivotTables can be added in 30 seconds from 'tbl_Cleaned_HR'.
A4: Cross-Tab 1: Active Headcount by Department vs. Job Level (COUNTIFS Matrix)
A5: Department | B5: L1 | C5: L2 | D5: L3 | E5: L4 | F5: L5 | G5: Total Active HC
A6: Engineering & Product | B6: =COUNTIFS(Cleaned_Data!$D$2:$D$1451,$A6,Cleaned_Data!$F$2:$F$1451,B$5,Cleaned_Data!$K$2:$K$1451,"Active") -> 141 | C6: =COUNTIFS(Cleaned_Data!$D$2:$D$1451,$A6,Cleaned_Data!$F$2:$F$1451,C$5,Cleaned_Data!$K$2:$K$1451,"Active") -> 131 | D6: =COUNTIFS(Cleaned_Data!$D$2:$D$1451,$A6,Cleaned_Data!$F$2:$F$1451,D$5,Cleaned_Data!$K$2:$K$1451,"Active") -> 51 | E6: =COUNTIFS(Cleaned_Data!$D$2:$D$1451,$A6,Cleaned_Data!$F$2:$F$1451,E$5,Cleaned_Data!$K$2:$K$1451,"Active") -> 28 | F6: =COUNTIFS(Cleaned_Data!$D$2:$D$1451,$A6,Cleaned_Data!$F$2:$F$1451,F$5,Cleaned_Data!$K$2:$K$1451,"Active") -> 15 | G6: =SUM(B6:F6) -> 366
A7: Enterprise Sales | B7: =COUNTIFS(Cleaned_Data!$D$2:$D$1451,$A7,Cleaned_Data!$F$2:$F$1451,B$5,Cleaned_Data!$K$2:$K$1451,"Active") -> 75 | C7: =COUNTIFS(Cleaned_Data!$D$2:$D$1451,$A7,Cleaned_Data!$F$2:$F$1451,C$5,Cleaned_Data!$K$2:$K$1451,"Active") -> 72 | D7: =COUNTIFS(Cleaned_Data!$D$2:$D$1451,$A7,Cleaned_Data!$F$2:$F$1451,D$5,Cleaned_Data!$K$2:$K$1451,"Active") -> 31 | E7: =COUNTIFS(Cleaned_Data!$D$2:$D$1451,$A7,Cleaned_Data!$F$2:$F$1451,E$5,Cleaned_Data!$K$2:$K$1451,"Active") -> 16 | F7: =COUNTIFS(Cleaned_Data!$D$2:$D$1451,$A7,Cleaned_Data!$F$2:$F$1451,F$5,Cleaned_Data!$K$2:$K$1451,"Active") -> 7 | G7: =SUM(B7:F7) -> 201
A8: Customer Operations | B8: =COUNTIFS(Cleaned_Data!$D$2:$D$1451,$A8,Cleaned_Data!$F$2:$F$1451,B$5,Cleaned_Data!$K$2:$K$1451,"Active") -> 48 | C8: =COUNTIFS(Cleaned_Data!$D$2:$D$1451,$A8,Cleaned_Data!$F$2:$F$1451,C$5,Cleaned_Data!$K$2:$K$1451,"Active") -> 67 | D8: =COUNTIFS(Cleaned_Data!$D$2:$D$1451,$A8,Cleaned_Data!$F$2:$F$1451,D$5,Cleaned_Data!$K$2:$K$1451,"Active") -> 32 | E8: =COUNTIFS(Cleaned_Data!$D$2:$D$1451,$A8,Cleaned_Data!$F$2:$F$1451,E$5,Cleaned_Data!$K$2:$K$1451,"Active") -> 15 | F8: =COUNTIFS(Cleaned_Data!$D$2:$D$1451,$A8,Cleaned_Data!$F$2:$F$1451,F$5,Cleaned_Data!$K$2:$K$1451,"Active") -> 6 | G8: =SUM(B8:F8) -> 168
A9: Growth Marketing | B9: =COUNTIFS(Cleaned_Data!$D$2:$D$1451,$A9,Cleaned_Data!$F$2:$F$1451,B$5,Cleaned_Data!$K$2:$K$1451,"Active") -> 47 | C9: =COUNTIFS(Cleaned_Data!$D$2:$D$1451,$A9,Cleaned_Data!$F$2:$F$1451,C$5,Cleaned_Data!$K$2:$K$1451,"Active") -> 39 | D9: =COUNTIFS(Cleaned_Data!$D$2:$D$1451,$A9,Cleaned_Data!$F$2:$F$1451,D$5,Cleaned_Data!$K$2:$K$1451,"Active") -> 19 | E9: =COUNTIFS(Cleaned_Data!$D$2:$D$1451,$A9,Cleaned_Data!$F$2:$F$1451,E$5,Cleaned_Data!$K$2:$K$1451,"Active") -> 13 | F9: =COUNTIFS(Cleaned_Data!$D$2:$D$1451,$A9,Cleaned_Data!$F$2:$F$1451,F$5,Cleaned_Data!$K$2:$K$1451,"Active") -> 1 | G9: =SUM(B9:F9) -> 119
A10: Finance & Strategy | B10: =COUNTIFS(Cleaned_Data!$D$2:$D$1451,$A10,Cleaned_Data!$F$2:$F$1451,B$5,Cleaned_Data!$K$2:$K$1451,"Active") -> 41 | C10: =COUNTIFS(Cleaned_Data!$D$2:$D$1451,$A10,Cleaned_Data!$F$2:$F$1451,C$5,Cleaned_Data!$K$2:$K$1451,"Active") -> 33 | D10: =COUNTIFS(Cleaned_Data!$D$2:$D$1451,$A10,Cleaned_Data!$F$2:$F$1451,D$5,Cleaned_Data!$K$2:$K$1451,"Active") -> 14 | E10: =COUNTIFS(Cleaned_Data!$D$2:$D$1451,$A10,Cleaned_Data!$F$2:$F$1451,E$5,Cleaned_Data!$K$2:$K$1451,"Active") -> 6 | F10: =COUNTIFS(Cleaned_Data!$D$2:$D$1451,$A10,Cleaned_Data!$F$2:$F$1451,F$5,Cleaned_Data!$K$2:$K$1451,"Active") -> 2 | G10: =SUM(B10:F10) -> 96
A11: People & Talent | B11: =COUNTIFS(Cleaned_Data!$D$2:$D$1451,$A11,Cleaned_Data!$F$2:$F$1451,B$5,Cleaned_Data!$K$2:$K$1451,"Active") -> 30 | C11: =COUNTIFS(Cleaned_Data!$D$2:$D$1451,$A11,Cleaned_Data!$F$2:$F$1451,C$5,Cleaned_Data!$K$2:$K$1451,"Active") -> 36 | D11: =COUNTIFS(Cleaned_Data!$D$2:$D$1451,$A11,Cleaned_Data!$F$2:$F$1451,D$5,Cleaned_Data!$K$2:$K$1451,"Active") -> 8 | E11: =COUNTIFS(Cleaned_Data!$D$2:$D$1451,$A11,Cleaned_Data!$F$2:$F$1451,E$5,Cleaned_Data!$K$2:$K$1451,"Active") -> 12 | F11: =COUNTIFS(Cleaned_Data!$D$2:$D$1451,$A11,Cleaned_Data!$F$2:$F$1451,F$5,Cleaned_Data!$K$2:$K$1451,"Active") -> 6 | G11: =SUM(B11:F11) -> 92
A12: Total Active by Level | B12: =SUM(B6:B11) -> 382 | C12: =SUM(C6:C11) -> 378 | D12: =SUM(D6:D11) -> 155 | E12: =SUM(E6:E11) -> 90 | F12: =SUM(F6:F11) -> 37 | G12: =SUM(G6:G11) -> 1042
A15: Cross-Tab 2: Attrition Rate Comparison — Overtime vs. Non-Overtime Cohorts by Department
A16: Department | B16: Overtime = Yes (Exits) | C16: Overtime = Yes (Attrition %) | D16: Overtime = No (Exits) | E16: Overtime = No (Attrition %)
A17: Engineering & Product | B17: =COUNTIFS(Cleaned_Data!$D$2:$D$1451,$A17,Cleaned_Data!$Q$2:$Q$1451,"Yes",Cleaned_Data!$K$2:$K$1451,"<>Active") -> 48 | C17: =IFERROR(B17/COUNTIFS(Cleaned_Data!$D$2:$D$1451,$A17,Cleaned_Data!$Q$2:$Q$1451,"Yes"),0) -> 0.32653061 | D17: =COUNTIFS(Cleaned_Data!$D$2:$D$1451,$A17,Cleaned_Data!$Q$2:$Q$1451,"No",Cleaned_Data!$K$2:$K$1451,"<>Active") -> 51 | E17: =IFERROR(D17/COUNTIFS(Cleaned_Data!$D$2:$D$1451,$A17,Cleaned_Data!$Q$2:$Q$1451,"No"),0) -> 0.16037736
A18: Enterprise Sales | B18: =COUNTIFS(Cleaned_Data!$D$2:$D$1451,$A18,Cleaned_Data!$Q$2:$Q$1451,"Yes",Cleaned_Data!$K$2:$K$1451,"<>Active") -> 69 | C18: =IFERROR(B18/COUNTIFS(Cleaned_Data!$D$2:$D$1451,$A18,Cleaned_Data!$Q$2:$Q$1451,"Yes"),0) -> 0.39655172 | D18: =COUNTIFS(Cleaned_Data!$D$2:$D$1451,$A18,Cleaned_Data!$Q$2:$Q$1451,"No",Cleaned_Data!$K$2:$K$1451,"<>Active") -> 31 | E18: =IFERROR(D18/COUNTIFS(Cleaned_Data!$D$2:$D$1451,$A18,Cleaned_Data!$Q$2:$Q$1451,"No"),0) -> 0.24409449
A19: Customer Operations | B19: =COUNTIFS(Cleaned_Data!$D$2:$D$1451,$A19,Cleaned_Data!$Q$2:$Q$1451,"Yes",Cleaned_Data!$K$2:$K$1451,"<>Active") -> 60 | C19: =IFERROR(B19/COUNTIFS(Cleaned_Data!$D$2:$D$1451,$A19,Cleaned_Data!$Q$2:$Q$1451,"Yes"),0) -> 0.4109589 | D19: =COUNTIFS(Cleaned_Data!$D$2:$D$1451,$A19,Cleaned_Data!$Q$2:$Q$1451,"No",Cleaned_Data!$K$2:$K$1451,"<>Active") -> 39 | E19: =IFERROR(D19/COUNTIFS(Cleaned_Data!$D$2:$D$1451,$A19,Cleaned_Data!$Q$2:$Q$1451,"No"),0) -> 0.32231405
A20: Growth Marketing | B20: =COUNTIFS(Cleaned_Data!$D$2:$D$1451,$A20,Cleaned_Data!$Q$2:$Q$1451,"Yes",Cleaned_Data!$K$2:$K$1451,"<>Active") -> 24 | C20: =IFERROR(B20/COUNTIFS(Cleaned_Data!$D$2:$D$1451,$A20,Cleaned_Data!$Q$2:$Q$1451,"Yes"),0) -> 0.39344262 | D20: =COUNTIFS(Cleaned_Data!$D$2:$D$1451,$A20,Cleaned_Data!$Q$2:$Q$1451,"No",Cleaned_Data!$K$2:$K$1451,"<>Active") -> 31 | E20: =IFERROR(D20/COUNTIFS(Cleaned_Data!$D$2:$D$1451,$A20,Cleaned_Data!$Q$2:$Q$1451,"No"),0) -> 0.27433628
A21: Finance & Strategy | B21: =COUNTIFS(Cleaned_Data!$D$2:$D$1451,$A21,Cleaned_Data!$Q$2:$Q$1451,"Yes",Cleaned_Data!$K$2:$K$1451,"<>Active") -> 15 | C21: =IFERROR(B21/COUNTIFS(Cleaned_Data!$D$2:$D$1451,$A21,Cleaned_Data!$Q$2:$Q$1451,"Yes"),0) -> 0.34883721 | D21: =COUNTIFS(Cleaned_Data!$D$2:$D$1451,$A21,Cleaned_Data!$Q$2:$Q$1451,"No",Cleaned_Data!$K$2:$K$1451,"<>Active") -> 16 | E21: =IFERROR(D21/COUNTIFS(Cleaned_Data!$D$2:$D$1451,$A21,Cleaned_Data!$Q$2:$Q$1451,"No"),0) -> 0.19047619
A22: People & Talent | B22: =COUNTIFS(Cleaned_Data!$D$2:$D$1451,$A22,Cleaned_Data!$Q$2:$Q$1451,"Yes",Cleaned_Data!$K$2:$K$1451,"<>Active") -> 14 | C22: =IFERROR(B22/COUNTIFS(Cleaned_Data!$D$2:$D$1451,$A22,Cleaned_Data!$Q$2:$Q$1451,"Yes"),0) -> 0.35897436 | D22: =COUNTIFS(Cleaned_Data!$D$2:$D$1451,$A22,Cleaned_Data!$Q$2:$Q$1451,"No",Cleaned_Data!$K$2:$K$1451,"<>Active") -> 10 | E22: =IFERROR(D22/COUNTIFS(Cleaned_Data!$D$2:$D$1451,$A22,Cleaned_Data!$Q$2:$Q$1451,"No"),0) -> 0.12987013
A25: Cross-Tab 3: Active Workforce Retention Risk Segmentation (High / Moderate / Low Risk)
A26: Department | B26: High Risk (Active) | C26: Moderate Risk (Active) | D26: Low Risk (Active) | E26: High Risk Share_%
A27: Engineering & Product | B27: =COUNTIFS(Cleaned_Data!$D$2:$D$1451,$A27,Cleaned_Data!$AF$2:$AF$1451,"High Risk") -> 54 | C27: =COUNTIFS(Cleaned_Data!$D$2:$D$1451,$A27,Cleaned_Data!$AF$2:$AF$1451,"Moderate Risk") -> 102 | D27: =COUNTIFS(Cleaned_Data!$D$2:$D$1451,$A27,Cleaned_Data!$AF$2:$AF$1451,"Low Risk") -> 210 | E27: =IFERROR(B27/SUM(B27:D27),0) -> 0.14754098
A28: Enterprise Sales | B28: =COUNTIFS(Cleaned_Data!$D$2:$D$1451,$A28,Cleaned_Data!$AF$2:$AF$1451,"High Risk") -> 53 | C28: =COUNTIFS(Cleaned_Data!$D$2:$D$1451,$A28,Cleaned_Data!$AF$2:$AF$1451,"Moderate Risk") -> 69 | D28: =COUNTIFS(Cleaned_Data!$D$2:$D$1451,$A28,Cleaned_Data!$AF$2:$AF$1451,"Low Risk") -> 79 | E28: =IFERROR(B28/SUM(B28:D28),0) -> 0.26368159
A29: Customer Operations | B29: =COUNTIFS(Cleaned_Data!$D$2:$D$1451,$A29,Cleaned_Data!$AF$2:$AF$1451,"High Risk") -> 44 | C29: =COUNTIFS(Cleaned_Data!$D$2:$D$1451,$A29,Cleaned_Data!$AF$2:$AF$1451,"Moderate Risk") -> 61 | D29: =COUNTIFS(Cleaned_Data!$D$2:$D$1451,$A29,Cleaned_Data!$AF$2:$AF$1451,"Low Risk") -> 63 | E29: =IFERROR(B29/SUM(B29:D29),0) -> 0.26190476
A30: Growth Marketing | B30: =COUNTIFS(Cleaned_Data!$D$2:$D$1451,$A30,Cleaned_Data!$AF$2:$AF$1451,"High Risk") -> 20 | C30: =COUNTIFS(Cleaned_Data!$D$2:$D$1451,$A30,Cleaned_Data!$AF$2:$AF$1451,"Moderate Risk") -> 31 | D30: =COUNTIFS(Cleaned_Data!$D$2:$D$1451,$A30,Cleaned_Data!$AF$2:$AF$1451,"Low Risk") -> 68 | E30: =IFERROR(B30/SUM(B30:D30),0) -> 0.16806723
A31: Finance & Strategy | B31: =COUNTIFS(Cleaned_Data!$D$2:$D$1451,$A31,Cleaned_Data!$AF$2:$AF$1451,"High Risk") -> 17 | C31: =COUNTIFS(Cleaned_Data!$D$2:$D$1451,$A31,Cleaned_Data!$AF$2:$AF$1451,"Moderate Risk") -> 22 | D31: =COUNTIFS(Cleaned_Data!$D$2:$D$1451,$A31,Cleaned_Data!$AF$2:$AF$1451,"Low Risk") -> 57 | E31: =IFERROR(B31/SUM(B31:D31),0) -> 0.17708333
A32: People & Talent | B32: =COUNTIFS(Cleaned_Data!$D$2:$D$1451,$A32,Cleaned_Data!$AF$2:$AF$1451,"High Risk") -> 15 | C32: =COUNTIFS(Cleaned_Data!$D$2:$D$1451,$A32,Cleaned_Data!$AF$2:$AF$1451,"Moderate Risk") -> 23 | D32: =COUNTIFS(Cleaned_Data!$D$2:$D$1451,$A32,Cleaned_Data!$AF$2:$AF$1451,"Low Risk") -> 54 | E32: =IFERROR(B32/SUM(B32:D32),0) -> 0.16304348
A33: Total Active Risk Pool | B33: =SUM(B27:B32) -> 203 | C33: =SUM(C27:C32) -> 308 | D33: =SUM(D27:D32) -> 531 | E33: =IFERROR(B33/SUM(B33:D33),0) -> 0.19481766

Sheet Cleaned_Data
A1: Employee_ID | B1: Full_Name | C1: Dept_Code | D1: Department | E1: Job_Level_Code | F1: Job_Level | G1: Job_Title | H1: Location | I1: Work_Mode | J1: Hire_Date | K1: Employment_Status | L1: Exit_Date | M1: Exit_Reason | N1: Recruitment_Source | O1: Annual_Salary_INR | P1: Performance_Rating | Q1: Overtime_Flag | R1: Training_Hours | S1: Manager_ID | T1: Emp_Serial_MID | U1: Dept_Abbr_LEFT | V1: Level_Check_RIGHT | W1: Manager_Name_VLOOKUP | X1: Cost_Center_VLOOKUP | Y1: Salary_Band_INDEX_MATCH | Z1: Band_Midpoint_XLOOKUP | AA1: Compa_Ratio | AB1: Hire_Year | AC1: Exit_Year | AD1: Tenure_Years | AE1: Tenure_Band_IF | AF1: Retention_Risk_Flag
A2: EMP-11004 | B2: Aarav Shah | C2: DEP-MKT | D2: Growth Marketing | E2: MKT-L1 | F2: L1 | G2: Marketing Associate | H2: Remote-India | I2: Remote | J2: 43466 | K2: Active | M2: N/A - Active | N2: Employee Referral | O2: 674000 | P2: 5 | Q2: No | R2: 31 | S2: MGR-602 | T2: =VALUE(MID(A2,5,5)) -> 11004 | U2: =LEFT(E2,3) -> MKT | V2: =RIGHT(E2,2) -> L1 | W2: =PROPER(TRIM(VLOOKUP(S2,Employee_Lookups!$I$4:$M$19,2,FALSE()))) -> Arjun Sengupta | X2: =VLOOKUP(C2,Employee_Lookups!$A$4:$G$9,4,FALSE()) -> CC-606 | Y2: =INDEX(Employee_Lookups!$C$13:$C$17,MATCH(F2,Employee_Lookups!$A$13:$A$17,0)) -> Band A (Entry) | Z2: =_xlfn.XLOOKUP(F2,Employee_Lookups!$A$13:$A$17,Employee_Lookups!$E$13:$E$17,0) -> 700000 | AA2: =ROUND(O2/INDEX(Employee_Lookups!$E$13:$E$17,MATCH(F2,Employee_Lookups!$A$13:$A$17,0)),3) -> 0.963 | AB2: =YEAR(J2) -> 2019 | AC2: =IF(ISBLANK(L2),"",YEAR(L2)) | AD2: =ROUND((IF(ISBLANK(L2),Employee_Lookups!$O$14,L2)-J2)/365.25,2) -> 7 | AE2: =IF(AD2<1,"< 1 Yr (New)",IF(AD2<3,"1 - 3 Yrs",IF(AD2<5,"3 - 5 Yrs","5+ Yrs"))) -> 5+ Yrs | AF2: =IF(K2<>"Active","Exited",IF(AND(Q2="Yes",OR(P2>=4,AA2<0.95)),"High Risk",IF(OR(Q2="Yes",AND(NOT(ISBLANK(P2)),P2<=2)),"Moderate Risk","Low Risk"))) -> Low Risk
A3: EMP-10815 | B3: Pranav Chitnis | C3: DEP-OPS | D3: Customer Operations | E3: OPS-L4 | F3: L4 | G3: Director of Operations | H3: Pune | I3: Hybrid | J3: 43470 | K3: Involuntary Exit | L3: 45702 | M3: Performance / Restructuring | N3: Campus Recruitment | O3: 2693000 | P3: 2 | Q3: Yes | R3: 32 | S3: MGR-302 | T3: =VALUE(MID(A3,5,5)) -> 10815 | U3: =LEFT(E3,3) -> OPS | V3: =RIGHT(E3,2) -> L4 | W3: =PROPER(TRIM(VLOOKUP(S3,Employee_Lookups!$I$4:$M$19,2,FALSE()))) -> Deepak Patil | X3: =VLOOKUP(C3,Employee_Lookups!$A$4:$G$9,4,FALSE()) -> CC-303 | Y3: =INDEX(Employee_Lookups!$C$13:$C$17,MATCH(F3,Employee_Lookups!$A$13:$A$17,0)) -> Band D (Leadership) | Z3: =_xlfn.XLOOKUP(F3,Employee_Lookups!$A$13:$A$17,Employee_Lookups!$E$13:$E$17,0) -> 2750000 | AA3: =ROUND(O3/INDEX(Employee_Lookups!$E$13:$E$17,MATCH(F3,Employee_Lookups!$A$13:$A$17,0)),3) -> 0.979 | AB3: =YEAR(J3) -> 2019 | AC3: =IF(ISBLANK(L3),"",YEAR(L3)) -> 2025 | AD3: =ROUND((IF(ISBLANK(L3),Employee_Lookups!$O$14,L3)-J3)/365.25,2) -> 6.11 | AE3: =IF(AD3<1,"< 1 Yr (New)",IF(AD3<3,"1 - 3 Yrs",IF(AD3<5,"3 - 5 Yrs","5+ Yrs"))) -> 5+ Yrs | AF3: =IF(K3<>"Active","Exited",IF(AND(Q3="Yes",OR(P3>=4,AA3<0.95)),"High Risk",IF(OR(Q3="Yes",AND(NOT(ISBLANK(P3)),P3<=2)),"Moderate Risk","Low Risk"))) -> Exited
A4: EMP-10751 | B4: Vihaan Menon | C4: DEP-ENG | D4: Engineering & Product | E4: ENG-L2 | F4: L2 | G4: Software Engineer II | H4: Bengaluru | I4: Hybrid | J4: 43471 | K4: Active | M4: N/A - Active | N4: Company Career Portal | O4: 1088000 | P4: 3 | Q4: No | R4: 42 | S4: MGR-101 | T4: =VALUE(MID(A4,5,5)) -> 10751 | U4: =LEFT(E4,3) -> ENG | V4: =RIGHT(E4,2) -> L2 | W4: =PROPER(TRIM(VLOOKUP(S4,Employee_Lookups!$I$4:$M$19,2,FALSE()))) -> Aarav Deshmukh | X4: =VLOOKUP(C4,Employee_Lookups!$A$4:$G$9,4,FALSE()) -> CC-101 | Y4: =INDEX(Employee_Lookups!$C$13:$C$17,MATCH(F4,Employee_Lookups!$A$13:$A$17,0)) -> Band B (Mid) | Z4: =_xlfn.XLOOKUP(F4,Employee_Lookups!$A$13:$A$17,Employee_Lookups!$E$13:$E$17,0) -> 1100000 | AA4: =ROUND(O4/INDEX(Employee_Lookups!$E$13:$E$17,MATCH(F4,Employee_Lookups!$A$13:$A$17,0)),3) -> 0.989 | AB4: =YEAR(J4) -> 2019 | AC4: =IF(ISBLANK(L4),"",YEAR(L4)) | AD4: =ROUND((IF(ISBLANK(L4),Employee_Lookups!$O$14,L4)-J4)/365.25,2) -> 6.98 | AE4: =IF(AD4<1,"< 1 Yr (New)",IF(AD4<3,"1 - 3 Yrs",IF(AD4<5,"3 - 5 Yrs","5+ Yrs"))) -> 5+ Yrs | AF4: =IF(K4<>"Active","Exited",IF(AND(Q4="Yes",OR(P4>=4,AA4<0.95)),"High Risk",IF(OR(Q4="Yes",AND(NOT(ISBLANK(P4)),P4<=2)),"Moderate Risk","Low Risk"))) -> Low Risk
A5: EMP-10863 | B5: Yash Bhatt | C5: DEP-ENG | D5: Engineering & Product | E5: ENG-L1 | F5: L1 | G5: Software Engineer I | H5: Hyderabad | I5: On-Site | J5: 43479 | K5: Active | M5: N/A - Active | N5: Employee Referral | O5: 586000 | P5: 5 | Q5: No | R5: 48 | S5: MGR-101 | T5: =VALUE(MID(A5,5,5)) -> 10863 | U5: =LEFT(E5,3) -> ENG | V5: =RIGHT(E5,2) -> L1 | W5: =PROPER(TRIM(VLOOKUP(S5,Employee_Lookups!$I$4:$M$19,2,FALSE()))) -> Aarav Deshmukh | X5: =VLOOKUP(C5,Employee_Lookups!$A$4:$G$9,4,FALSE()) -> CC-101 | Y5: =INDEX(Employee_Lookups!$C$13:$C$17,MATCH(F5,Employee_Lookups!$A$13:$A$17,0)) -> Band A (Entry) | Z5: =_xlfn.XLOOKUP(F5,Employee_Lookups!$A$13:$A$17,Employee_Lookups!$E$13:$E$17,0) -> 700000 | AA5: =ROUND(O5/INDEX(Employee_Lookups!$E$13:$E$17,MATCH(F5,Employee_Lookups!$A$13:$A$17,0)),3) -> 0.837 | AB5: =YEAR(J5) -> 2019 | AC5: =IF(ISBLANK(L5),"",YEAR(L5)) | AD5: =ROUND((IF(ISBLANK(L5),Employee_Lookups!$O$14,L5)-J5)/365.25,2) -> 6.96 | AE5: =IF(AD5<1,"< 1 Yr (New)",IF(AD5<3,"1 - 3 Yrs",IF(AD5<5,"3 - 5 Yrs","5+ Yrs"))) -> 5+ Yrs | AF5: =IF(K5<>"Active","Exited",IF(AND(Q5="Yes",OR(P5>=4,AA5<0.95)),"High Risk",IF(OR(Q5="Yes",AND(NOT(ISBLANK(P5)),P5<=2)),"Moderate Risk","Low Risk"))) -> Low Risk
A6: EMP-10356 | B6: Ananya Reddy | C6: DEP-SAL | D6: Enterprise Sales | E6: SAL-L2 | F6: L2 | G6: Account Executive | H6: Pune | I6: Hybrid | J6: 43479 | K6: Voluntary Exit | L6: 44170 | M6: Higher Education | N6: Campus Recruitment | O6: 1194000 | P6: 3 | Q6: Yes | R6: 24 | S6: MGR-202 | T6: =VALUE(MID(A6,5,5)) -> 10356 | U6: =LEFT(E6,3) -> SAL | V6: =RIGHT(E6,2) -> L2 | W6: =PROPER(TRIM(VLOOKUP(S6,Employee_Lookups!$I$4:$M$19,2,FALSE()))) -> Priya Sharma | X6: =VLOOKUP(C6,Employee_Lookups!$A$4:$G$9,4,FALSE()) -> CC-202 | Y6: =INDEX(Employee_Lookups!$C$13:$C$17,MATCH(F6,Employee_Lookups!$A$13:$A$17,0)) -> Band B (Mid) | Z6: =_xlfn.XLOOKUP(F6,Employee_Lookups!$A$13:$A$17,Employee_Lookups!$E$13:$E$17,0) -> 1100000 | AA6: =ROUND(O6/INDEX(Employee_Lookups!$E$13:$E$17,MATCH(F6,Employee_Lookups!$A$13:$A$17,0)),3) -> 1.085 | AB6: =YEAR(J6) -> 2019 | AC6: =IF(ISBLANK(L6),"",YEAR(L6)) -> 2020 | AD6: =ROUND((IF(ISBLANK(L6),Employee_Lookups!$O$14,L6)-J6)/365.25,2) -> 1.89 | AE6: =IF(AD6<1,"< 1 Yr (New)",IF(AD6<3,"1 - 3 Yrs",IF(AD6<5,"3 - 5 Yrs","5+ Yrs"))) -> 1 - 3 Yrs | AF6: =IF(K6<>"Active","Exited",IF(AND(Q6="Yes",OR(P6>=4,AA6<0.95)),"High Risk",IF(OR(Q6="Yes",AND(NOT(ISBLANK(P6)),P6<=2)),"Moderate Risk","Low Risk"))) -> Exited
A7: EMP-10463 | B7: Pranav Malhotra | C7: DEP-SAL | D7: Enterprise Sales | E7: SAL-L3 | F7: L3 | G7: Regional Sales Manager | H7: Bengaluru | I7: Hybrid | J7: 43483 | K7: Voluntary Exit | L7: 43789 | M7: Higher Education | N7: LinkedIn Sourcing | O7: 1630000 | P7: 5 | Q7: Yes | R7: 40 | S7: MGR-201 | T7: =VALUE(MID(A7,5,5)) -> 10463 | U7: =LEFT(E7,3) -> SAL | V7: =RIGHT(E7,2) -> L3 | W7: =PROPER(TRIM(VLOOKUP(S7,Employee_Lookups!$I$4:$M$19,2,FALSE()))) -> Vikramaditya Joshi | X7: =VLOOKUP(C7,Employee_Lookups!$A$4:$G$9,4,FALSE()) -> CC-202 | Y7: =INDEX(Employee_Lookups!$C$13:$C$17,MATCH(F7,Employee_Lookups!$A$13:$A$17,0)) -> Band C (Senior) | Z7: =_xlfn.XLOOKUP(F7,Employee_Lookups!$A$13:$A$17,Employee_Lookups!$E$13:$E$17,0) -> 1725000 | AA7: =ROUND(O7/INDEX(Employee_Lookups!$E$13:$E$17,MATCH(F7,Employee_Lookups!$A$13:$A$17,0)),3) -> 0.945 | AB7: =YEAR(J7) -> 2019 | AC7: =IF(ISBLANK(L7),"",YEAR(L7)) -> 2019 | AD7: =ROUND((IF(ISBLANK(L7),Employee_Lookups!$O$14,L7)-J7)/365.25,2) -> 0.84 | AE7: =IF(AD7<1,"< 1 Yr (New)",IF(AD7<3,"1 - 3 Yrs",IF(AD7<5,"3 - 5 Yrs","5+ Yrs"))) -> < 1 Yr (New) | AF7: =IF(K7<>"Active","Exited",IF(AND(Q7="Yes",OR(P7>=4,AA7<0.95)),"High Risk",IF(OR(Q7="Yes",AND(NOT(ISBLANK(P7)),P7<=2)),"Moderate Risk","Low Risk"))) -> Exited
A8: EMP-11114 | B8: Ira Patil | C8: DEP-ENG | D8: Engineering & Product | E8: ENG-L1 | F8: L1 | G8: Software Engineer I | H8: Bengaluru | I8: Hybrid | J8: 43484 | K8: Active | M8: N/A - Active | N8: Campus Recruitment | O8: 696000 | P8: 4 | Q8: Yes | R8: 31 | S8: MGR-103 | T8: =VALUE(MID(A8,5,5)) -> 11114 | U8: =LEFT(E8,3) -> ENG | V8: =RIGHT(E8,2) -> L1 | W8: =PROPER(TRIM(VLOOKUP(S8,Employee_Lookups!$I$4:$M$19,2,FALSE()))) -> Rohan Verma | X8: =VLOOKUP(C8,Employee_Lookups!$A$4:$G$9,4,FALSE()) -> CC-101 | Y8: =INDEX(Employee_Lookups!$C$13:$C$17,MATCH(F8,Employee_Lookups!$A$13:$A$17,0)) -> Band A (Entry) | Z8: =_xlfn.XLOOKUP(F8,Employee_Lookups!$A$13:$A$17,Employee_Lookups!$E$13:$E$17,0) -> 700000 | AA8: =ROUND(O8/INDEX(Employee_Lookups!$E$13:$E$17,MATCH(F8,Employee_Lookups!$A$13:$A$17,0)),3) -> 0.994 | AB8: =YEAR(J8) -> 2019 | AC8: =IF(ISBLANK(L8),"",YEAR(L8)) | AD8: =ROUND((IF(ISBLANK(L8),Employee_Lookups!$O$14,L8)-J8)/365.25,2) -> 6.95 | AE8: =IF(AD8<1,"< 1 Yr (New)",IF(AD8<3,"1 - 3 Yrs",IF(AD8<5,"3 - 5 Yrs","5+ Yrs"))) -> 5+ Yrs | AF8: =IF(K8<>"Active","Exited",IF(AND(Q8="Yes",OR(P8>=4,AA8<0.95)),"High Risk",IF(OR(Q8="Yes",AND(NOT(ISBLANK(P8)),P8<=2)),"Moderate Risk","Low Risk"))) -> High Risk
A9: EMP-11174 | B9: Yash Joshi | C9: DEP-SAL | D9: Enterprise Sales | E9: SAL-L4 | F9: L4 | G9: Director of Enterprise Sales | H9: Bengaluru | I9: Hybrid | J9: 43485 | K9: Involuntary Exit | L9: 45713 | M9: Performance / Restructuring | N9: Campus Recruitment | O9: 3181000 | P9: 5 | Q9: Yes | R9: 46 | S9: MGR-202 | T9: =VALUE(MID(A9,5,5)) -> 11174 | U9: =LEFT(E9,3) -> SAL | V9: =RIGHT(E9,2) -> L4 | W9: =PROPER(TRIM(VLOOKUP(S9,Employee_Lookups!$I$4:$M$19,2,FALSE()))) -> Priya Sharma | X9: =VLOOKUP(C9,Employee_Lookups!$A$4:$G$9,4,FALSE()) -> CC-202 | Y9: =INDEX(Employee_Lookups!$C$13:$C$17,MATCH(F9,Employee_Lookups!$A$13:$A$17,0)) -> Band D (Leadership) | Z9: =_xlfn.XLOOKUP(F9,Employee_Lookups!$A$13:$A$17,Employee_Lookups!$E$13:$E$17,0) -> 2750000 | AA9: =ROUND(O9/INDEX(Employee_Lookups!$E$13:$E$17,MATCH(F9,Employee_Lookups!$A$13:$A$17,0)),3) -> 1.157 | AB9: =YEAR(J9) -> 2019 | AC9: =IF(ISBLANK(L9),"",YEAR(L9)) -> 2025 | AD9: =ROUND((IF(ISBLANK(L9),Employee_Lookups!$O$14,L9)-J9)/365.25,2) -> 6.1 | AE9: =IF(AD9<1,"< 1 Yr (New)",IF(AD9<3,"1 - 3 Yrs",IF(AD9<5,"3 - 5 Yrs","5+ Yrs"))) -> 5+ Yrs | AF9: =IF(K9<>"Active","Exited",IF(AND(Q9="Yes",OR(P9>=4,AA9<0.95)),"High Risk",IF(OR(Q9="Yes",AND(NOT(ISBLANK(P9)),P9<=2)),"Moderate Risk","Low Risk"))) -> Exited
A10: EMP-10746 | B10: Tejas Rao | C10: DEP-ENG | D10: Engineering & Product | E10: ENG-L1 | F10: L1 | G10: Software Engineer I | H10: Pune | I10: Hybrid | J10: 43486 | K10: Involuntary Exit | L10: 43637 | M10: Performance / Restructuring | N10: Company Career Portal | O10: 601000 | P10: 2 | Q10: No | R10: 16 | S10: MGR-103 | T10: =VALUE(MID(A10,5,5)) -> 10746 | U10: =LEFT(E10,3) -> ENG | V10: =RIGHT(E10,2) -> L1 | W10: =PROPER(TRIM(VLOOKUP(S10,Employee_Lookups!$I$4:$M$19,2,FALSE()))) -> Rohan Verma | X10: =VLOOKUP(C10,Employee_Lookups!$A$4:$G$9,4,FALSE()) -> CC-101 | Y10: =INDEX(Employee_Lookups!$C$13:$C$17,MATCH(F10,Employee_Lookups!$A$13:$A$17,0)) -> Band A (Entry) | Z10: =_xlfn.XLOOKUP(F10,Employee_Lookups!$A$13:$A$17,Employee_Lookups!$E$13:$E$17,0) -> 700000 | AA10: =ROUND(O10/INDEX(Employee_Lookups!$E$13:$E$17,MATCH(F10,Employee_Lookups!$A$13:$A$17,0)),3) -> 0.859 | AB10: =YEAR(J10) -> 2019 | AC10: =IF(ISBLANK(L10),"",YEAR(L10)) -> 2019 | AD10: =ROUND((IF(ISBLANK(L10),Employee_Lookups!$O$14,L10)-J10)/365.25,2) -> 0.41 | AE10: =IF(AD10<1,"< 1 Yr (New)",IF(AD10<3,"1 - 3 Yrs",IF(AD10<5,"3 - 5 Yrs","5+ Yrs"))) -> < 1 Yr (New) | AF10: =IF(K10<>"Active","Exited",IF(AND(Q10="Yes",OR(P10>=4,AA10<0.95)),"High Risk",IF(OR(Q10="Yes",AND(NOT(ISBLANK(P10)),P10<=2)),"Moderate Risk","Low Risk"))) -> Exited
A11: EMP-11431 | B11: Pranav Joshi | C11: DEP-FIN | D11: Finance & Strategy | E11: FIN-L1 | F11: L1 | G11: Financial Analyst | H11: Bengaluru | I11: Hybrid | J11: 43492 | K11: Active | M11: N/A - Active | N11: Company Career Portal | O11: 757000 | P11: 5 | Q11: No | R11: 25 | S11: MGR-401 | T11: =VALUE(MID(A11,5,5)) -> 11431 | U11: =LEFT(E11,3) -> FIN | V11: =RIGHT(E11,2) -> L1 | W11: =PROPER(TRIM(VLOOKUP(S11,Employee_Lookups!$I$4:$M$19,2,FALSE()))) -> Rajeshwari Rao | X11: =VLOOKUP(C11,Employee_Lookups!$A$4:$G$9,4,FALSE()) -> CC-404 | Y11: =INDEX(Employee_Lookups!$C$13:$C$17,MATCH(F11,Employee_Lookups!$A$13:$A$17,0)) -> Band A (Entry) | Z11: =_xlfn.XLOOKUP(F11,Employee_Lookups!$A$13:$A$17,Employee_Lookups!$E$13:$E$17,0) -> 700000 | AA11: =ROUND(O11/INDEX(Employee_Lookups!$E$13:$E$17,MATCH(F11,Employee_Lookups!$A$13:$A$17,0)),3) -> 1.081 | AB11: =YEAR(J11) -> 2019 | AC11: =IF(ISBLANK(L11),"",YEAR(L11)) | AD11: =ROUND((IF(ISBLANK(L11),Employee_Lookups!$O$14,L11)-J11)/365.25,2) -> 6.93 | AE11: =IF(AD11<1,"< 1 Yr (New)",IF(AD11<3,"1 - 3 Yrs",IF(AD11<5,"3 - 5 Yrs","5+ Yrs"))) -> 5+ Yrs | AF11: =IF(K11<>"Active","Exited",IF(AND(Q11="Yes",OR(P11>=4,AA11<0.95)),"High Risk",IF(OR(Q11="Yes",AND(NOT(ISBLANK(P11)),P11<=2)),"Moderate Risk","Low Risk"))) -> Low Risk
A12: EMP-10360 | B12: Neha Sharma | C12: DEP-FIN | D12: Finance & Strategy | E12: FIN-L2 | F12: L2 | G12: Senior FP&A Analyst | H12: Bengaluru | I12: Hybrid | J12: 43504 | K12: Voluntary Exit | L12: 43692 | M12: Career Growth | N12: LinkedIn Sourcing | O12: 1215000 | P12: 3 | Q12: No | R12: 38 | S12: MGR-402 | T12: =VALUE(MID(A12,5,5)) -> 10360 | U12: =LEFT(E12,3) -> FIN | V12: =RIGHT(E12,2) -> L2 | W12: =PROPER(TRIM(VLOOKUP(S12,Employee_Lookups!$I$4:$M$19,2,FALSE()))) -> Aditya Gokhale | X12: =VLOOKUP(C12,Employee_Lookups!$A$4:$G$9,4,FALSE()) -> CC-404 | Y12: =INDEX(Employee_Lookups!$C$13:$C$17,MATCH(F12,Employee_Lookups!$A$13:$A$17,0)) -> Band B (Mid) | Z12: =_xlfn.XLOOKUP(F12,Employee_Lookups!$A$13:$A$17,Employee_Lookups!$E$13:$E$17,0) -> 1100000 | AA12: =ROUND(O12/INDEX(Employee_Lookups!$E$13:$E$17,MATCH(F12,Employee_Lookups!$A$13:$A$17,0)),3) -> 1.105 | AB12: =YEAR(J12) -> 2019 | AC12: =IF(ISBLANK(L12),"",YEAR(L12)) -> 2019 | AD12: =ROUND((IF(ISBLANK(L12),Employee_Lookups!$O$14,L12)-J12)/365.25,2) -> 0.51 | AE12: =IF(AD12<1,"< 1 Yr (New)",IF(AD12<3,"1 - 3 Yrs",IF(AD12<5,"3 - 5 Yrs","5+ Yrs"))) -> < 1 Yr (New) | AF12: =IF(K12<>"Active","Exited",IF(AND(Q12="Yes",OR(P12>=4,AA12<0.95)),"High Risk",IF(OR(Q12="Yes",AND(NOT(ISBLANK(P12)),P12<=2)),"Moderate Risk","Low Risk"))) -> Exited
A13: EMP-10920 | B13: Shruti Joshi | C13: DEP-ENG | D13: Engineering & Product | E13: ENG-L3 | F13: L3 | G13: Engineering Manager | H13: Pune | I13: Hybrid | J13: 43508 | K13: Involuntary Exit | L13: 43803 | M13: Performance / Restructuring | N13: LinkedIn Sourcing | O13: 2001000 | P13: 4 | Q13: Yes | R13: 32 | S13: MGR-102 | T13: =VALUE(MID(A13,5,5)) -> 10920 | U13: =LEFT(E13,3) -> ENG | V13: =RIGHT(E13,2) -> L3 | W13: =PROPER(TRIM(VLOOKUP(S13,Employee_Lookups!$I$4:$M$19,2,FALSE()))) -> Neha Kulkarni | X13: =VLOOKUP(C13,Employee_Lookups!$A$4:$G$9,4,FALSE()) -> CC-101 | Y13: =INDEX(Employee_Lookups!$C$13:$C$17,MATCH(F13,Employee_Lookups!$A$13:$A$17,0)) -> Band C (Senior) | Z13: =_xlfn.XLOOKUP(F13,Employee_Lookups!$A$13:$A$17,Employee_Lookups!$E$13:$E$17,0) -> 1725000 | AA13: =ROUND(O13/INDEX(Employee_Lookups!$E$13:$E$17,MATCH(F13,Employee_Lookups!$A$13:$A$17,0)),3) -> 1.16 | AB13: =YEAR(J13) -> 2019 | AC13: =IF(ISBLANK(L13),"",YEAR(L13)) -> 2019 | AD13: =ROUND((IF(ISBLANK(L13),Employee_Lookups!$O$14,L13)-J13)/365.25,2) -> 0.81 | AE13: =IF(AD13<1,"< 1 Yr (New)",IF(AD13<3,"1 - 3 Yrs",IF(AD13<5,"3 - 5 Yrs","5+ Yrs"))) -> < 1 Yr (New) | AF13: =IF(K13<>"Active","Exited",IF(AND(Q13="Yes",OR(P13>=4,AA13<0.95)),"High Risk",IF(OR(Q13="Yes",AND(NOT(ISBLANK(P13)),P13<=2)),"Moderate Risk","Low Risk"))) -> Exited
A14: EMP-10123 | B14: Diya Verma | C14: DEP-MKT | D14: Growth Marketing | E14: MKT-L2 | F14: L2 | G14: Growth Specialist | H14: Bengaluru | I14: Hybrid | J14: 43516 | K14: Voluntary Exit | L14: 44142 | M14: Career Growth | N14: LinkedIn Sourcing | O14: 1160000 | P14: 5 | Q14: No | R14: 38 | S14: MGR-601 | T14: =VALUE(MID(A14,5,5)) -> 10123 | U14: =LEFT(E14,3) -> MKT | V14: =RIGHT(E14,2) -> L2 | W14: =PROPER(TRIM(VLOOKUP(S14,Employee_Lookups!$I$4:$M$19,2,FALSE()))) -> Tanvi Chitnis | X14: =VLOOKUP(C14,Employee_Lookups!$A$4:$G$9,4,FALSE()) -> CC-606 | Y14: =INDEX(Employee_Lookups!$C$13:$C$17,MATCH(F14,Employee_Lookups!$A$13:$A$17,0)) -> Band B (Mid) | Z14: =_xlfn.XLOOKUP(F14,Employee_Lookups!$A$13:$A$17,Employee_Lookups!$E$13:$E$17,0) -> 1100000 | AA14: =ROUND(O14/INDEX(Employee_Lookups!$E$13:$E$17,MATCH(F14,Employee_Lookups!$A$13:$A$17,0)),3) -> 1.055 | AB14: =YEAR(J14) -> 2019 | AC14: =IF(ISBLANK(L14),"",YEAR(L14)) -> 2020 | AD14: =ROUND((IF(ISBLANK(L14),Employee_Lookups!$O$14,L14)-J14)/365.25,2) -> 1.71 | AE14: =IF(AD14<1,"< 1 Yr (New)",IF(AD14<3,"1 - 3 Yrs",IF(AD14<5,"3 - 5 Yrs","5+ Yrs"))) -> 1 - 3 Yrs | AF14: =IF(K14<>"Active","Exited",IF(AND(Q14="Yes",OR(P14>=4,AA14<0.95)),"High Risk",IF(OR(Q14="Yes",AND(NOT(ISBLANK(P14)),P14<=2)),"Moderate Risk","Low Risk"))) -> Exited
A15: EMP-10426 | B15: Vihaan Sharma | C15: DEP-ENG | D15: Engineering & Product | E15: ENG-L2 | F15: L2 | G15: Software Engineer II | H15: Pune | I15: Hybrid | J15: 43518 | K15: Active | M15: N/A - Active | N15: LinkedIn Sourcing | O15: 1121000 | P15: 3 | Q15: Yes | R15: 20 | S15: MGR-101 | T15: =VALUE(MID(A15,5,5)) -> 10426 | U15: =LEFT(E15,3) -> ENG | V15: =RIGHT(E15,2) -> L2 | W15: =PROPER(TRIM(VLOOKUP(S15,Employee_Lookups!$I$4:$M$19,2,FALSE()))) -> Aarav Deshmukh | X15: =VLOOKUP(C15,Employee_Lookups!$A$4:$G$9,4,FALSE()) -> CC-101 | Y15: =INDEX(Employee_Lookups!$C$13:$C$17,MATCH(F15,Employee_Lookups!$A$13:$A$17,0)) -> Band B (Mid) | Z15: =_xlfn.XLOOKUP(F15,Employee_Lookups!$A$13:$A$17,Employee_Lookups!$E$13:$E$17,0) -> 1100000 | AA15: =ROUND(O15/INDEX(Employee_Lookups!$E$13:$E$17,MATCH(F15,Employee_Lookups!$A$13:$A$17,0)),3) -> 1.019 | AB15: =YEAR(J15) -> 2019 | AC15: =IF(ISBLANK(L15),"",YEAR(L15)) | AD15: =ROUND((IF(ISBLANK(L15),Employee_Lookups!$O$14,L15)-J15)/365.25,2) -> 6.86 | AE15: =IF(AD15<1,"< 1 Yr (New)",IF(AD15<3,"1 - 3 Yrs",IF(AD15<5,"3 - 5 Yrs","5+ Yrs"))) -> 5+ Yrs | AF15: =IF(K15<>"Active","Exited",IF(AND(Q15="Yes",OR(P15>=4,AA15<0.95)),"High Risk",IF(OR(Q15="Yes",AND(NOT(ISBLANK(P15)),P15<=2)),"Moderate Risk","Low Risk"))) -> Moderate Risk
A16: EMP-10013 | B16: Krishna Sengupta | C16: DEP-OPS | D16: Customer Operations | E16: OPS-L2 | F16: L2 | G16: Customer Success Specialist | H16: Bengaluru | I16: Hybrid | J16: 43521 | K16: Active | M16: N/A - Active | N16: Employee Referral | O16: 905000 | P16: 3 | Q16: Yes | R16: 37 | S16: MGR-302 | T16: =VALUE(MID(A16,5,5)) -> 10013 | U16: =LEFT(E16,3) -> OPS | V16: =RIGHT(E16,2) -> L2 | W16: =PROPER(TRIM(VLOOKUP(S16,Employee_Lookups!$I$4:$M$19,2,FALSE()))) -> Deepak Patil | X16: =VLOOKUP(C16,Employee_Lookups!$A$4:$G$9,4,FALSE()) -> CC-303 | Y16: =INDEX(Employee_Lookups!$C$13:$C$17,MATCH(F16,Employee_Lookups!$A$13:$A$17,0)) -> Band B (Mid) | Z16: =_xlfn.XLOOKUP(F16,Employee_Lookups!$A$13:$A$17,Employee_Lookups!$E$13:$E$17,0) -> 1100000 | AA16: =ROUND(O16/INDEX(Employee_Lookups!$E$13:$E$17,MATCH(F16,Employee_Lookups!$A$13:$A$17,0)),3) -> 0.823 | AB16: =YEAR(J16) -> 2019 | AC16: =IF(ISBLANK(L16),"",YEAR(L16)) | AD16: =ROUND((IF(ISBLANK(L16),Employee_Lookups!$O$14,L16)-J16)/365.25,2) -> 6.85 | AE16: =IF(AD16<1,"< 1 Yr (New)",IF(AD16<3,"1 - 3 Yrs",IF(AD16<5,"3 - 5 Yrs","5+ Yrs"))) -> 5+ Yrs | AF16: =IF(K16<>"Active","Exited",IF(AND(Q16="Yes",OR(P16>=4,AA16<0.95)),"High Risk",IF(OR(Q16="Yes",AND(NOT(ISBLANK(P16)),P16<=2)),"Moderate Risk","Low Risk"))) -> High Risk
A17: EMP-10687 | B17: Omkar Sharma | C17: DEP-MKT | D17: Growth Marketing | E17: MKT-L1 | F17: L1 | G17: Marketing Associate | H17: Hyderabad | I17: On-Site | J17: 43530 | K17: Voluntary Exit | L17: 45397 | M17: Higher Education | N17: External Agency | O17: 565000 | P17: 3 | Q17: No | R17: 24 | S17: MGR-601 | T17: =VALUE(MID(A17,5,5)) -> 10687 | U17: =LEFT(E17,3) -> MKT | V17: =RIGHT(E17,2) -> L1 | W17: =PROPER(TRIM(VLOOKUP(S17,Employee_Lookups!$I$4:$M$19,2,FALSE()))) -> Tanvi Chitnis | X17: =VLOOKUP(C17,Employee_Lookups!$A$4:$G$9,4,FALSE()) -> CC-606 | Y17: =INDEX(Employee_Lookups!$C$13:$C$17,MATCH(F17,Employee_Lookups!$A$13:$A$17,0)) -> Band A (Entry) | Z17: =_xlfn.XLOOKUP(F17,Employee_Lookups!$A$13:$A$17,Employee_Lookups!$E$13:$E$17,0) -> 700000 | AA17: =ROUND(O17/INDEX(Employee_Lookups!$E$13:$E$17,MATCH(F17,Employee_Lookups!$A$13:$A$17,0)),3) -> 0.807 | AB17: =YEAR(J17) -> 2019 | AC17: =IF(ISBLANK(L17),"",YEAR(L17)) -> 2024 | AD17: =ROUND((IF(ISBLANK(L17),Employee_Lookups!$O$14,L17)-J17)/365.25,2) -> 5.11 | AE17: =IF(AD17<1,"< 1 Yr (New)",IF(AD17<3,"1 - 3 Yrs",IF(AD17<5,"3 - 5 Yrs","5+ Yrs"))) -> 5+ Yrs | AF17: =IF(K17<>"Active","Exited",IF(AND(Q17="Yes",OR(P17>=4,AA17<0.95)),"High Risk",IF(OR(Q17="Yes",AND(NOT(ISBLANK(P17)),P17<=2)),"Moderate Risk","Low Risk"))) -> Exited
